<?xml version="1.0" encoding="utf-8"?>
<!-- This URDF was automatically created by SolidWorks to URDF Exporter! Originally created by Stephen Brawner (brawner@gmail.com) 
     Commit Version: 1.6.0-4-g7f85cfe  Build Version: 1.6.7995.38578
     For more information, please see http://wiki.ros.org/sw_urdf_exporter -->
<robot
  name="5DOF.SLDASM">
  <link
    name="base_link">
    <inertial>
      <origin
        xyz="0.1016 0.00320411469759873 0.0508"
        rpy="0 0 0" />
      <mass
        value="0.127147471977805" />
      <inertia
        ixx="0.000111831356264364"
        ixy="-2.72450714762173E-22"
        ixz="-2.7400357790819E-21"
        iyy="0.000561119002312225"
        iyz="3.57128977824887E-22"
        izz="0.000450144258992043" />
    </inertial>
    <visual>
      <origin
        xyz="0 0 0"
        rpy="0 0 0" />
      <geometry>
        <mesh
          filename="package://5DOF.SLDASM/meshes/base_link.STL" />
      </geometry>
      <material
        name="">
        <color
          rgba="0.792156862745098 0.819607843137255 0.933333333333333 1" />
      </material>
    </visual>
    <collision>
      <origin
        xyz="0 0 0"
        rpy="0 0 0" />
      <geometry>
        <mesh
          filename="package://5DOF.SLDASM/meshes/base_link.STL" />
      </geometry>
    </collision>
  </link>
  <link
    name="Link1">
    <inertial>
      <origin
        xyz="-0.00156634735052255 0.00304728813828482 -6.93889390390723E-18"
        rpy="0 0 0" />
      <mass
        value="0.0289860326782574" />
      <inertia
        ixx="1.5223794318669E-05"
        ixy="5.79839891169716E-09"
        ixz="8.73502726855997E-22"
        iyy="2.99544476674964E-05"
        iyz="1.03397576569128E-25"
        izz="1.49289111118974E-05" />
    </inertial>
    <visual>
      <origin
        xyz="0 0 0"
        rpy="0 0 0" />
      <geometry>
        <mesh
          filename="package://5DOF.SLDASM/meshes/Link1.STL" />
      </geometry>
      <material
        name="">
        <color
          rgba="0.792156862745098 0.819607843137255 0.933333333333333 1" />
      </material>
    </visual>
    <collision>
      <origin
        xyz="0 0 0"
        rpy="0 0 0" />
      <geometry>
        <mesh
          filename="package://5DOF.SLDASM/meshes/Link1.STL" />
      </geometry>
    </collision>
  </link>
  <joint
    name="Joint1"
    type="continuous">
    <origin
      xyz="0.1036 -0.05084 0.03635"
      rpy="1.5708 0 -0.025571" />
    <parent
      link="base_link" />
    <child
      link="Link1" />
    <axis
      xyz="0 1 0" />
  </joint>
  <link
    name="Link2">
    <inertial>
      <origin
        xyz="-0.14573663352729 -4.64905891561784E-16 0.00995966285328655"
        rpy="0 0 0" />
      <mass
        value="0.0727270945890701" />
      <inertia
        ixx="1.17404497835575E-05"
        ixy="-2.18110983917982E-19"
        ixz="2.94224835162662E-19"
        iyy="0.000580856987066852"
        iyz="0"
        izz="0.000592108680471815" />
    </inertial>
    <visual>
      <origin
        xyz="0 0 0"
        rpy="0 0 0" />
      <geometry>
        <mesh
          filename="package://5DOF.SLDASM/meshes/Link2.STL" />
      </geometry>
      <material
        name="">
        <color
          rgba="0.792156862745098 0.819607843137255 0.933333333333333 1" />
      </material>
    </visual>
    <collision>
      <origin
        xyz="0 0 0"
        rpy="0 0 0" />
      <geometry>
        <mesh
          filename="package://5DOF.SLDASM/meshes/Link2.STL" />
      </geometry>
    </collision>
  </link>
  <joint
    name="Joint2"
    type="continuous">
    <origin
      xyz="0.00016534 0.050763 0.0019121"
      rpy="-1.5708 0.71678 -1.5708" />
    <parent
      link="Link1" />
    <child
      link="Link2" />
    <axis
      xyz="0 0 -1" />
  </joint>
  <link
    name="Link3">
    <inertial>
      <origin
        xyz="-0.151997210961116 -0.0120375282676248 -2.22044604925031E-16"
        rpy="0 0 0" />
      <mass
        value="0.090914548707032" />
      <inertia
        ixx="1.63114517143676E-05"
        ixy="8.7151749338587E-19"
        ixz="9.38936022031392E-19"
        iyy="0.000837589789847113"
        iyz="-2.5410988417629E-20"
        izz="0.000821889321781119" />
    </inertial>
    <visual>
      <origin
        xyz="0 0 0"
        rpy="0 0 0" />
      <geometry>
        <mesh
          filename="package://5DOF.SLDASM/meshes/Link3.STL" />
      </geometry>
      <material
        name="">
        <color
          rgba="0.792156862745098 0.819607843137255 0.933333333333333 1" />
      </material>
    </visual>
    <collision>
      <origin
        xyz="0 0 0"
        rpy="0 0 0" />
      <geometry>
        <mesh
          filename="package://5DOF.SLDASM/meshes/Link3.STL" />
      </geometry>
    </collision>
  </link>
  <joint
    name="Joint3"
    type="continuous">
    <origin
      xyz="-0.2774 0 -0.015403"
      rpy="1.5708 0 1.2521" />
    <parent
      link="Link2" />
    <child
      link="Link3" />
    <axis
      xyz="0 1 0" />
  </joint>
  <link
    name="Link4">
    <inertial>
      <origin
        xyz="1.11022302462516E-16 0.00317956626937047 0.00110175974049123"
        rpy="0 0 0" />
      <mass
        value="0.0257561871549524" />
      <inertia
        ixx="1.65551442883999E-05"
        ixy="4.3754545681605E-20"
        ixz="-1.0351196013818E-21"
        iyy="2.60799221135831E-05"
        iyz="-4.35135151210531E-09"
        izz="9.69751079128943E-06" />
    </inertial>
    <visual>
      <origin
        xyz="0 0 0"
        rpy="0 0 0" />
      <geometry>
        <mesh
          filename="package://5DOF.SLDASM/meshes/Link4.STL" />
      </geometry>
      <material
        name="">
        <color
          rgba="0.792156862745098 0.819607843137255 0.933333333333333 1" />
      </material>
    </visual>
    <collision>
      <origin
        xyz="0 0 0"
        rpy="0 0 0" />
      <geometry>
        <mesh
          filename="package://5DOF.SLDASM/meshes/Link4.STL" />
      </geometry>
    </collision>
  </link>
  <joint
    name="Joint4"
    type="continuous">
    <origin
      xyz="-0.30216 -0.052613 0.00078978"
      rpy="0 -0.3981 0" />
    <parent
      link="Link3" />
    <child
      link="Link4" />
    <axis
      xyz="0 1 0" />
  </joint>
  <link
    name="Link5">
    <inertial>
      <origin
        xyz="-1.0178854148446E-08 4.93707069393334E-08 0.00894882267425838"
        rpy="0 0 0" />
      <mass
        value="0.00713826707604841" />
      <inertia
        ixx="9.1234372827186E-07"
        ixy="2.8081665507336E-13"
        ixz="-2.67286641151399E-12"
        iyy="9.12343403576146E-07"
        iyz="2.09703351846591E-12"
        izz="1.66070034774805E-06" />
    </inertial>
    <visual>
      <origin
        xyz="0 0 0"
        rpy="0 0 0" />
      <geometry>
        <mesh
          filename="package://5DOF.SLDASM/meshes/Link5.STL" />
      </geometry>
      <material
        name="">
        <color
          rgba="0.752941176470588 0.752941176470588 0.752941176470588 1" />
      </material>
    </visual>
    <collision>
      <origin
        xyz="0 0 0"
        rpy="0 0 0" />
      <geometry>
        <mesh
          filename="package://5DOF.SLDASM/meshes/Link5.STL" />
      </geometry>
    </collision>
  </link>
  <joint
    name="Joint5"
    type="continuous">
    <origin
      xyz="-0.0019997 -0.031718 0.072325"
      rpy="0 0 -2.8294" />
    <parent
      link="Link4" />
    <child
      link="Link5" />
    <axis
      xyz="0 0 -1" />
  </joint>
</robot>